[2020-05-03 11:15:12,368] {/home/alta12/foldervenv/venvpro/lib/python3.6/site-packages/flask/app.py:1892} ERROR - Exception on /client [POST]
Traceback (most recent call last):
  File "/home/alta12/foldervenv/venvpro/lib/python3.6/site-packages/flask/app.py", line 1950, in full_dispatch_request
    rv = self.dispatch_request()
  File "/home/alta12/foldervenv/venvpro/lib/python3.6/site-packages/flask/app.py", line 1936, in dispatch_request
    return self.view_functions[rule.endpoint](**req.view_args)
  File "/home/alta12/foldervenv/venvpro/lib/python3.6/site-packages/flask_restful/__init__.py", line 468, in wrapper
    resp = resource(*args, **kwargs)
  File "/home/alta12/foldervenv/venvpro/lib/python3.6/site-packages/flask/views.py", line 89, in view
    return self.dispatch_request(*args, **kwargs)
  File "/home/alta12/foldervenv/venvpro/lib/python3.6/site-packages/flask_restful/__init__.py", line 583, in dispatch_request
    resp = meth(*args, **kwargs)
  File "/home/alta12/Videos/E-COMMERCE/asa-ecommerce/blueprints/client/resources.py", line 34, in post
    app.logger.debug('DEBUG: %s', client)
NameError: name 'app' is not defined
[2020-05-03 11:15:12,369] {/home/alta12/Videos/E-COMMERCE/asa-ecommerce/blueprints/__init__.py:89} ERROR - REQUEST_LOG	{"method": "POST", "code": "500 INTERNAL SERVER ERROR", "uri": "/client?", "request": {"nama_pengguna": "asa", "kata_kunci": "alta123", "status": "admin"}, "response": {"message": "Internal Server Error"}}
[2020-05-03 11:17:41,404] {/home/alta12/foldervenv/venvpro/lib/python3.6/site-packages/flask/app.py:1892} ERROR - Exception on /client [POST]
Traceback (most recent call last):
  File "/home/alta12/foldervenv/venvpro/lib/python3.6/site-packages/sqlalchemy/engine/base.py", line 1248, in _execute_context
    cursor, statement, parameters, context
  File "/home/alta12/foldervenv/venvpro/lib/python3.6/site-packages/sqlalchemy/engine/default.py", line 590, in do_execute
    cursor.execute(statement, parameters)
  File "/home/alta12/foldervenv/venvpro/lib/python3.6/site-packages/pymysql/cursors.py", line 170, in execute
    result = self._query(query)
  File "/home/alta12/foldervenv/venvpro/lib/python3.6/site-packages/pymysql/cursors.py", line 328, in _query
    conn.query(q)
  File "/home/alta12/foldervenv/venvpro/lib/python3.6/site-packages/pymysql/connections.py", line 517, in query
    self._affected_rows = self._read_query_result(unbuffered=unbuffered)
  File "/home/alta12/foldervenv/venvpro/lib/python3.6/site-packages/pymysql/connections.py", line 732, in _read_query_result
    result.read()
  File "/home/alta12/foldervenv/venvpro/lib/python3.6/site-packages/pymysql/connections.py", line 1075, in read
    first_packet = self.connection._read_packet()
  File "/home/alta12/foldervenv/venvpro/lib/python3.6/site-packages/pymysql/connections.py", line 684, in _read_packet
    packet.check_error()
  File "/home/alta12/foldervenv/venvpro/lib/python3.6/site-packages/pymysql/protocol.py", line 220, in check_error
    err.raise_mysql_exception(self._data)
  File "/home/alta12/foldervenv/venvpro/lib/python3.6/site-packages/pymysql/err.py", line 109, in raise_mysql_exception
    raise errorclass(errno, errval)
pymysql.err.IntegrityError: (1062, "Duplicate entry 'asa' for key 'nama_pengguna'")

The above exception was the direct cause of the following exception:

Traceback (most recent call last):
  File "/home/alta12/foldervenv/venvpro/lib/python3.6/site-packages/flask/app.py", line 1950, in full_dispatch_request
    rv = self.dispatch_request()
  File "/home/alta12/foldervenv/venvpro/lib/python3.6/site-packages/flask/app.py", line 1936, in dispatch_request
    return self.view_functions[rule.endpoint](**req.view_args)
  File "/home/alta12/foldervenv/venvpro/lib/python3.6/site-packages/flask_restful/__init__.py", line 468, in wrapper
    resp = resource(*args, **kwargs)
  File "/home/alta12/foldervenv/venvpro/lib/python3.6/site-packages/flask/views.py", line 89, in view
    return self.dispatch_request(*args, **kwargs)
  File "/home/alta12/foldervenv/venvpro/lib/python3.6/site-packages/flask_restful/__init__.py", line 583, in dispatch_request
    resp = meth(*args, **kwargs)
  File "/home/alta12/Videos/E-COMMERCE/asa-ecommerce/blueprints/client/resources.py", line 32, in post
    db.session.commit()
  File "/home/alta12/foldervenv/venvpro/lib/python3.6/site-packages/sqlalchemy/orm/scoping.py", line 162, in do
    return getattr(self.registry(), name)(*args, **kwargs)
  File "/home/alta12/foldervenv/venvpro/lib/python3.6/site-packages/sqlalchemy/orm/session.py", line 1036, in commit
    self.transaction.commit()
  File "/home/alta12/foldervenv/venvpro/lib/python3.6/site-packages/sqlalchemy/orm/session.py", line 503, in commit
    self._prepare_impl()
  File "/home/alta12/foldervenv/venvpro/lib/python3.6/site-packages/sqlalchemy/orm/session.py", line 482, in _prepare_impl
    self.session.flush()
  File "/home/alta12/foldervenv/venvpro/lib/python3.6/site-packages/sqlalchemy/orm/session.py", line 2496, in flush
    self._flush(objects)
  File "/home/alta12/foldervenv/venvpro/lib/python3.6/site-packages/sqlalchemy/orm/session.py", line 2637, in _flush
    transaction.rollback(_capture_exception=True)
  File "/home/alta12/foldervenv/venvpro/lib/python3.6/site-packages/sqlalchemy/util/langhelpers.py", line 69, in __exit__
    exc_value, with_traceback=exc_tb,
  File "/home/alta12/foldervenv/venvpro/lib/python3.6/site-packages/sqlalchemy/util/compat.py", line 178, in raise_
    raise exception
  File "/home/alta12/foldervenv/venvpro/lib/python3.6/site-packages/sqlalchemy/orm/session.py", line 2597, in _flush
    flush_context.execute()
  File "/home/alta12/foldervenv/venvpro/lib/python3.6/site-packages/sqlalchemy/orm/unitofwork.py", line 422, in execute
    rec.execute(self)
  File "/home/alta12/foldervenv/venvpro/lib/python3.6/site-packages/sqlalchemy/orm/unitofwork.py", line 589, in execute
    uow,
  File "/home/alta12/foldervenv/venvpro/lib/python3.6/site-packages/sqlalchemy/orm/persistence.py", line 245, in save_obj
    insert,
  File "/home/alta12/foldervenv/venvpro/lib/python3.6/site-packages/sqlalchemy/orm/persistence.py", line 1136, in _emit_insert_statements
    statement, params
  File "/home/alta12/foldervenv/venvpro/lib/python3.6/site-packages/sqlalchemy/engine/base.py", line 984, in execute
    return meth(self, multiparams, params)
  File "/home/alta12/foldervenv/venvpro/lib/python3.6/site-packages/sqlalchemy/sql/elements.py", line 293, in _execute_on_connection
    return connection._execute_clauseelement(self, multiparams, params)
  File "/home/alta12/foldervenv/venvpro/lib/python3.6/site-packages/sqlalchemy/engine/base.py", line 1103, in _execute_clauseelement
    distilled_params,
  File "/home/alta12/foldervenv/venvpro/lib/python3.6/site-packages/sqlalchemy/engine/base.py", line 1288, in _execute_context
    e, statement, parameters, cursor, context
  File "/home/alta12/foldervenv/venvpro/lib/python3.6/site-packages/sqlalchemy/engine/base.py", line 1482, in _handle_dbapi_exception
    sqlalchemy_exception, with_traceback=exc_info[2], from_=e
  File "/home/alta12/foldervenv/venvpro/lib/python3.6/site-packages/sqlalchemy/util/compat.py", line 178, in raise_
    raise exception
  File "/home/alta12/foldervenv/venvpro/lib/python3.6/site-packages/sqlalchemy/engine/base.py", line 1248, in _execute_context
    cursor, statement, parameters, context
  File "/home/alta12/foldervenv/venvpro/lib/python3.6/site-packages/sqlalchemy/engine/default.py", line 590, in do_execute
    cursor.execute(statement, parameters)
  File "/home/alta12/foldervenv/venvpro/lib/python3.6/site-packages/pymysql/cursors.py", line 170, in execute
    result = self._query(query)
  File "/home/alta12/foldervenv/venvpro/lib/python3.6/site-packages/pymysql/cursors.py", line 328, in _query
    conn.query(q)
  File "/home/alta12/foldervenv/venvpro/lib/python3.6/site-packages/pymysql/connections.py", line 517, in query
    self._affected_rows = self._read_query_result(unbuffered=unbuffered)
  File "/home/alta12/foldervenv/venvpro/lib/python3.6/site-packages/pymysql/connections.py", line 732, in _read_query_result
    result.read()
  File "/home/alta12/foldervenv/venvpro/lib/python3.6/site-packages/pymysql/connections.py", line 1075, in read
    first_packet = self.connection._read_packet()
  File "/home/alta12/foldervenv/venvpro/lib/python3.6/site-packages/pymysql/connections.py", line 684, in _read_packet
    packet.check_error()
  File "/home/alta12/foldervenv/venvpro/lib/python3.6/site-packages/pymysql/protocol.py", line 220, in check_error
    err.raise_mysql_exception(self._data)
  File "/home/alta12/foldervenv/venvpro/lib/python3.6/site-packages/pymysql/err.py", line 109, in raise_mysql_exception
    raise errorclass(errno, errval)
sqlalchemy.exc.IntegrityError: (pymysql.err.IntegrityError) (1062, "Duplicate entry 'asa' for key 'nama_pengguna'")
[SQL: INSERT INTO client (nama_pengguna, kata_kunci, salt, status, updated_at) VALUES (%(nama_pengguna)s, %(kata_kunci)s, %(salt)s, %(status)s, %(updated_at)s)]
[parameters: {'nama_pengguna': 'asa', 'kata_kunci': '713b01f70a1c3b77dec9a8c260b2c73ac142a0dc7b23d5a11fc1e00dd7c347a479a79dbbf3598950df152fdcc301bb5e4d7479802666708f10caaedaaebacc6f', 'salt': 'bf455dac0ee14994bebf7f88e340411d', 'status': 'admin', 'updated_at': None}]
(Background on this error at: http://sqlalche.me/e/gkpj)
[2020-05-03 11:17:41,437] {/home/alta12/Videos/E-COMMERCE/asa-ecommerce/blueprints/__init__.py:89} ERROR - REQUEST_LOG	{"method": "POST", "code": "500 INTERNAL SERVER ERROR", "uri": "/client?", "request": {"nama_pengguna": "asa", "kata_kunci": "alta123", "status": "admin"}, "response": {"message": "Internal Server Error"}}
